Workbook

Sheet Task_Distribution
C2: What? | H2: Who? | I2: Progress | J2: Overleaf
C3: Part 1: Assessment of the reference aircraft | I3: Not started | J3: Not Started
C4: a) | D4: Familiarize | H4: Matej, sofia, rik, marcos, theo, toñas | I4: 0.75 | J4: Not Started | K4: some pdfs in the teams
C5: b) | D5: Generate | H5: sofia | I5: Done | J5: Done
C6: I. | E6: Table | H6: sofia | I6: Done | J6: Done
C7: II. | E7: Pie chart | H7: sofia | I7: Done | J7: Done
C8: c) | D8: Generate a table from the weight breakdown | H8: Matej, Rik, Marcos, Theo, | I8: Done | J8: Not Started
C9: I. | E9: Fuselage and wing group | H9: Matej, Rik, Marcos, Theo, | I9: Done | J9: 0.25
C10: II. | E10: Calculate the cg of groups and components | H10: Matej, Rik, Marcos, Theo, | I10: Done | J10: Not Started
C11: 1. | F11: one global system positioned ahead | H11: Matej, Rik, Marcos, Theo, | I11: Done | J11: Not Started
C12: 2. | F12: system fixed at LEMAC | H12: Matej, Rik, Marcos, Theo, | I12: Done | J12: Not Started
C13: d) | D13: Generate aircraft loading diagram | H13: Théotime | I13: 0.75 | J13: Not Started
C14: e) | D14: Identify most aft and forward CG positions | H14: Matej | I14: Not Started | J14: Not Started
C15: I. | E15: Report them in a table | I15: Not Started | J15: Not Started
C16: f) | D16: Report all geometry and aero parameters for stability and controllability [see e) in second part] | H16: Matej, sofia | I16: 0.25 | J16: 0.25
C17: g) | D17: Generate scissor plot | H17: Matej | I17: 0.25 | J17: Not Started
C18: Part 2: Evaluation of design modifications | I18: Not Started | J18: Not Started
C19: a) | D19: generate a second weight table, similar to 1.b) | H19: Rik & Marcos | I19: 0.25 | J19: Not Started
C20: b) | D20: Updated CG data table similar to 1.c) | H20: Rik & Marcos | I20: 0.75 | J20: Not Started
C21: c) | D21: Loading diagrams similar to 1.d) | I21: Not Started | J21: Not Started
C22: d) | D22: Scissor plot [report both 1.g) and 2.d) in same figure] | I22: Not Started | J22: Not Started
C23: e) | D23: Table with necessary dats to built scissor plots | I23: Not Started | J23: Not Started
C24: f) | D24: Provide answers to customer questions [3.2 from a) to f) in reader] | I24: Not Started | J24: Not Started
C25: Part 3: Organisations of group | H25: Matej | I25: 0.5 | J25: Not Started
C26: a) | D26: appendix | H26: Matej | I26: Not Started | J26: Not Started

Sheet 1.b) Ref_ac
D2: abs [kg] | E2: %MTOW
B3: MTOW | D3: 38995 | E3: =(D3/$D$3)*100 -> 100
B4: OEW | D4: 23188 | E4: =(D4/$D$3)*100 -> 59.464034
B5: Fuel weight @ max payload | D5: 3841 | E5: =(D5/$D$3)*100 -> 9.8499808
B6: Max payload | C6: Max payload | D6: 11966 | E6: =(D6/$D$3)*100 -> 30.685985
C7: Pax&cabin luggage | D7: =D6-(D8+D9) -> 9197 | E7: =(D7/$D$3)*100 -> 23.585075
C8: Front cargo hold | D8: 962 | E8: =(D8/$D$3)*100 -> 2.4669829
C9: Aft cargo hold | D9: 1807 | E9: =(D9/$D$3)*100 -> 4.6339274
B12: Slice labels
B13: OEW
B14: Fuel weight @ max payload
B15: Max payload
B16: Pax&cabin luggage
B17: Front cargo hold
B18: Aft cargo hold

Sheet 1.c)
B3: EOW
B4: 23188 | C4: kg
B5: Table provided, expressed in percentage of the EOW | H5: Wing group | I5: mass (kg) | J5: XCG nose | K5: Xcg lemac | N5: Fuselage group | O5: mass (kg) | P5: XCG nose | Q5: Xcg lemac
B6: Component | C6: Weight (% EOW) | D6: mass (kg) | E6: OEW CG | H6: Wing | I6: =D7 -> 4568.036 | J6: =($I$6*C19+$I$7*C23)/$I$8 -> 20.861433 | K6: =($I$6*D19+$I$7*D23)/$I$8 -> 1.1062987 | N6: propulsion | O6: =D13 -> 3084.004 | P6: =($O$6*C25+$O$7*C22+$O$8*C21+$O$9*C20+$O$10*C26+$O$11*C24)/SUM($O$6:$O$11) -> 20.815803 | Q6: =($O$6*D25+$O$7*D22+$O$8*D21+$O$9*D20+$O$10*D26+$O$11*D24)/SUM($O$6:$O$11) -> 1.0606688
B7: Wing | C7: 19.7 | D7: =C7/100 *$B$4 -> 4568.036 | E7: =SUMPRODUCT(D7:D14,C19:C26)/D15 -> 20.830133 | F7: from nose | H7: main landing gear | I7: =D11 -> 1344.904 | N7: fuselage | O7: =D10 -> 8115.8
B8: Horizontal Tail | C8: 2.5 | D8: =C8/100 *$B$4 -> 579.7 | E8: =SUMPRODUCT(D7:D14,D19:D26)/D15 -> 1.0749984 | F8: from LEMAC | H8: Total | I8: =SUM(I6:I7) -> 5912.94 | N8: vertical tail | O8: =D9 -> 417.384
B9: Vertical Tail | C9: 1.8 | D9: =C9/100 *$B$4 -> 417.384 | F9: lemac | N9: horizontal tail | O9: =D8 -> 579.7
B10: Fuselage | C10: 35 | D10: =C10/100 *$B$4 -> 8115.8 | N10: cockpit | O10: =D14 -> 533.324
B11: Main Landing gear | C11: 5.8 | D11: =C11/100 *$B$4 -> 1344.904 | N11: nose landing gear | O11: =D12 -> 185.504
B12: Nose Landing gear | C12: 0.8 | D12: =C12/100 *$B$4 -> 185.504 | N12: Total | O12: =SUM(O6:O11) -> 12915.716
B13: Propulsion System | C13: 13.3 | D13: =C13/100 *$B$4 -> 3084.004
B14: Cockpit Systems | C14: 2.3 | D14: =C14/100 *$B$4 -> 533.324
B15: Total | C15: =SUM(C7:C14) -> 81.2 | D15: =C15/100 *$B$4 -> 18828.656
B18: CG | C18: cg position from front | D18: position from LEMAC | H18: CRJ1000 geometry | I18: dist | J18: unit | L18: Horizontal Tail Geometry | M18: dist | N18: unit | P18: Vertical tail Geometry | Q18: dist | R18: unit
B19: Wing | C19: 20.829469 | D19: =C19-$C$27 -> 1.0743348 | E19: [m] | H19: Fuselage length | I19: 36.466 | J19: m | L19: Horizontal Tail span | M19: 8.541 | N19: m | P19: Vert tail height | Q19: 3.4081177 | R19: m
B20: Horizontal Tail | C20: =M22+M23+M24 -> 36.951365 | D20: =C20-$C$27 -> 17.19623 | E20: [m] | H20: Nose to front of nacelles | I20: 28.29114 | J20: m | L20: Hor Tail cg y location | M20: =0.38*M19/2 -> 1.62279 | N20: m | P20: Vert tail vert cg pos | Q20: =0.55*Q19 -> 1.8744647 | R20: m
B21: Vertical Tail | C21: =Q22+Q23 -> 35.166369 | D21: =C21-$C$27 -> 15.411234 | E21: [m] | H21: Length of engines | I21: 3.9 | J21: m | L21: Hor Tail MAC | M21: 2.0974891 | N21: m | P21: Ver tail MAC | Q21: 2.807975 | R21: m
B22: Fuselage | C22: =0.47*I19 -> 17.13902 | D22: =C22-$C$27 -> -2.6161144 | E22: [m] | H22: Wing geometry | L22: Hor Tail cg x location from front of MAC | M22: =0.42*M21 -> 0.88094544 | N22: m | P22: Ver tail LEMAC to cg | Q22: =0.42*Q21 -> 1.1793495 | R22: m
B23: Main Landing gear | C23: 20.97 | D23: =C23-$C$27 -> 1.2148656 | E23: [m] | H23: Lateral CG pos | I23: =0.35*C31/2 -> 4.580625 | J23: m | L23: Distance from LEMAC to tip of hor tail | M23: 0.95887735 | N23: m | P23: Nose to vert tail LEMAC | Q23: 33.987019 | R23: m
B24: Nose Landing gear | C24: 2.17 | D24: =C24-$C$27 -> -17.585134 | E24: [m] | H24: c_s (inside wing no control surfaces?) | I24: 1.8894243 | J24: m | L24: Nose to tip of hor tail | M24: 35.111542 | N24: m
B25: Propulsion System | C25: =I20+0.4*I21 -> 29.85114 | D25: =C25-$C$27 -> 10.096006 | E25: [m]
B26: Cockpit Systems | C26: =4.47/2 -> 2.235 | D26: =C26-$C$27 -> -17.520134 | E26: [m]
B27: nose to lemac | C27: =19.75513439 -> 19.755134
B29: LEMAC Calculation prerequisites | E29: source
B30: Wing surface | C30: 77.39 | D30: [m2] | E30: CPJ1000APMR8
B31: wing span | C31: 26.175 | D31: [m] | E31: CPJ1000APMR8
B32: taper | C32: 0.23812887 | D32: [-] | E32: CPJ1000APMR8
B33: root chord | C33: 5.8879795 | D33: [m] | E33: CRJ1000APMR8
B34: tip chord | C34: =C33*C32 -> 1.4020979 | D34: [m] | E34: CPJ1000APMR8
B35: sweep | C35: 30 | D35: degrees | E35: CPJ1000APMR8
B36: aspect ratio | C36: =C31*C31/C30 -> 8.8529607 | D36: [-] | E36: CPJ1000APMR8
B41: number passangers | C41: 100
B42: n rows | C42: =C41/C43 -> 20
B43: seat per row | C43: 5
B44: seat pitch | C44: =31*0.0254 -> 0.7874 | D44: [m]
B45: first row longitudinal position | C45: 6.75 | D45: [m]
B46: passenger mass per | C46: 90 | D46: [kg]
E48: MAC | F48: 4.11
C49: MAC: 4.11, Position: (5.20, -3.45)
C50: AC Position: (5.20, -4.47)
...

Sheet 1.d)

Sheet 1.e)

Sheet 1.g)
P2: Stability | Q2: Control
C3: A.C parameters required | D3: symbol | E3: value | G3: STABILITY | K3: CONTROL | O3: X_cg | P3: Sh/S (stab) | Q3: Sh/S (control)
C4: MAC chord length. THIS IS TAKEN FROM THE mac PYTHON SCRIPT | D4: c_MAC | E4: 4.11 | G4: x_ac estimations (as percentages of MAC) | O4: 0 | P4: =(O4-H5+0.05)/(I13/I22*(1 - H33)*E17/E4*E18) -> 0.038744947 | Q4: =(O4 + M6/M7 - M10)/(M8/M7*E17/E4*E18) -> 0.297975
C5: wingspan | D5: b | E5: ='1.c)'!C31 -> 26.175 | G5: x_ac | H5: =H7+H6+H8+H9 -> -0.1649545 | K5: Var | L5: Symbol | O5: 0.01 | P5: =(O4-$H$5+0.05)/($I$13/$I$22*(1-$H$33)*$E$17/$E$4*$E$18) -> 0.038744947 | Q5: =(O4 + $M$6/$M$7 - $M$10)/($M$8/$M$7*$E$17/$E$4*$E$18) -> 0.297975
C6: fuselage width | D6: b_f | E6: 2.695 | G6: x_ac_w | K6: Zero-lift pitching moment of a.c without tail | L6: Cmac | M6: -0.15 | O6: 0.02 | P6: =(O5-$H$5+0.05)/($I$13/$I$22*(1-$H$33)*$E$17/$E$4*$E$18) -> 0.040547419 | Q6: =(O5 + $M$6/$M$7 - $M$10)/($M$8/$M$7*$E$17/$E$4*$E$18) -> 0.2907825
C7: fuselage height | D7: h_f | E7: 2.695 | G7: x_ac_f1 | H7: =-1.8*E6*E7*E8/(E9*E4*I22) -> -1.7856587 | L7: CL_Ah | M7: 0.7 | O7: 0.03 | P7: =(O6-$H$5+0.05)/($I$13/$I$22*(1-$H$33)*$E$17/$E$4*$E$18) -> 0.042349891 | Q7: =(O6 + $M$6/$M$7 - $M$10)/($M$8/$M$7*$E$17/$E$4*$E$18) -> 0.28359
C8: length of a.c nose to where the wing's leading edge touches the fuselage | D8: l_fn | E8: 17.09 | G8: x_ac_f2 | H8: =0.273*E6*E10*(E5-E6) * TAN(E11) / ((1 + E12)*E4*E4*(E5+2.15*E6)) -> 0.23976713 | K8: Tail lift coeff (-1 for full moving, -0,8 for adjustable,-0,35 for fixed tail) | L8: CL_h | M8: -0.8 | O8: 0.04 | P8: =(O7-$H$5+0.05)/($I$13/$I$22*(1-$H$33)*$E$17/$E$4*$E$18) -> 0.044152363 | Q8: =(O7 + $M$6/$M$7 - $M$10)/($M$8/$M$7*$E$17/$E$4*$E$18) -> 0.2763975
C9: wing surface | D9: S | E9: ='1.c)'!C30 -> 77.39 | G9: x_ac_n | H9: =E13*E13*E14/(E9*E4*I22)*E16*E15 -> 1.3809371 | O9: 0.05 | P9: =(O8-$H$5+0.05)/($I$13/$I$22*(1-$H$33)*$E$17/$E$4*$E$18) -> 0.045954835 | Q9: =(O8 + $M$6/$M$7 - $M$10)/($M$8/$M$7*$E$17/$E$4*$E$18) -> 0.269205
C10: NOT c.g I think ?? smth to do with x_ac_f2 | D10: c_g | E10: 30 | L10: Xac | M10: 0.2 | O10: 0.06 | P10: =(O9-$H$5+0.05)/($I$13/$I$22*(1-$H$33)*$E$17/$E$4*$E$18) -> 0.047757307 | Q10: =(O9 + $M$6/$M$7 - $M$10)/($M$8/$M$7*$E$17/$E$4*$E$18) -> 0.2620125
C11: Taper Ratio?? something else??? | D11: Lambda_0.25 | E11: 0.3 | O11: 0.07 | P11: =(O10-$H$5+0.05)/($I$13/$I$22*(1-$H$33)*$E$17/$E$4*$E$18) -> 0.049559779 | Q11: =(O10 + $M$6/$M$7 - $M$10)/($M$8/$M$7*$E$17/$E$4*$E$18) -> 0.25482
C12: taper ratio | D12: lambda | E12: ='1.c)'!C32 -> 0.23812887 | G12: Cla_H estimation | H12: symbol | I12: value | O12: 0.08 | P12: =(O11-$H$5+0.05)/($I$13/$I$22*(1-$H$33)*$E$17/$E$4*$E$18) -> 0.051362251 | Q12: =(O11 + $M$6/$M$7 - $M$10)/($M$8/$M$7*$E$17/$E$4*$E$18) -> 0.2476275
C13: nacelle width | D13: b_n | E13: 1.56 | G13: Change of Cl with alpha for the tail | H13: CLa_H | I13: =2*PI()*I17/(2 + SQRT(4 + (I17*I15/I16)^2*(1+TAN(I18)^2/I15^2))) -> 2.7599226 | O13: 0.09 | P13: =(O12-$H$5+0.05)/($I$13/$I$22*(1-$H$33)*$E$17/$E$4*$E$18) -> 0.053164723 | Q13: =(O12 + $M$6/$M$7 - $M$10)/($M$8/$M$7*$E$17/$E$4*$E$18) -> 0.240435
C14: longitudinal distance of the engine-s furthest point from the quarter/cord of the MAC. The engine being more forward than the MAC is a positive l and more aft is negative l | D14: l_n | E14: -14.2 | G14: Mach num for tail | H14: M_h | I14: 0.48 | O14: 0.1 | P14: =(O13-$H$5+0.05)/($I$13/$I$22*(1-$H$33)*$E$17/$E$4*$E$18) -> 0.054967195 | Q14: =(O13 + $M$6/$M$7 - $M$10)/($M$8/$M$7*$E$17/$E$4*$E$18) -> 0.2332425
C15: number of engines | E15: 2 | F15: . | G15: NO idea but has to do with mach | H15: Beta_h | I15: =SQRT(1-I14*I14) -> 0.87726849 | O15: 0.11 | P15: =(O14-$H$5+0.05)/($I$13/$I$22*(1-$H$33)*$E$17/$E$4*$E$18) -> 0.056769668 | Q15: =(O14 + $M$6/$M$7 - $M$10)/($M$8/$M$7*$E$17/$E$4*$E$18) -> 0.22605
C16: nacelle constant k, -4 fornacelles on the LE of wing or fuselage nose, -2,5 for engines mounted on the rear fuselage | D16: k | E16: -2.5 | G16: no idea | H16: Eta_h | I16: 0.5 | O16: 0.12 | P16: =(O15-$H$5+0.05)/($I$13/$I$22*(1-$H$33)*$E$17/$E$4*$E$18) -> 0.05857214 | Q16: =(O15 + $M$6/$M$7 - $M$10)/($M$8/$M$7*$E$17/$E$4*$E$18) -> 0.2188575
C17: Probably the tail length???? IM NOT RLY SURE | D17: l_h | E17: 5 | G17: IM GUESSING aspect ratio of wing | H17: A_h | I17: 10 | O17: 0.13 | P17: =(O16-$H$5+0.05)/($I$13/$I$22*(1-$H$33)*$E$17/$E$4*$E$18) -> 0.060374612 | Q17: =(O16 + $M$6/$M$7 - $M$10)/($M$8/$M$7*$E$17/$E$4*$E$18) -> 0.211665
C18: Ratio of tail speed to wing speed squared | D18: (V_h/V)^2 | E18: 1 | G18: Taper ratio 0.5??? idk | H18: Lambda_0.5_w | I18: 0.5 | O18: 0.14 | P18: =(O17-$H$5+0.05)/($I$13/$I$22*(1-$H$33)*$E$17/$E$4*$E$18) -> 0.062177084 | Q18: =(O17 + $M$6/$M$7 - $M$10)/($M$8/$M$7*$E$17/$E$4*$E$18) -> 0.2044725
C19: 0,85 if fuselage-mounted, 0,95 if fin-mounted and 1 if T-tail or canard | O19: 0.15 | P19: =(O18-$H$5+0.05)/($I$13/$I$22*(1-$H$33)*$E$17/$E$4*$E$18) -> 0.063979556 | Q19: =(O18 + $M$6/$M$7 - $M$10)/($M$8/$M$7*$E$17/$E$4*$E$18) -> 0.19728
C20: Aspect Ratio of the wing | D20: A_w | E20: ='1.c)'!C36 -> 8.8529607 | O20: 0.16 | P20: =(O19-$H$5+0.05)/($I$13/$I$22*(1-$H$33)*$E$17/$E$4*$E$18) -> 0.065782028 | Q20: =(O19 + $M$6/$M$7 - $M$10)/($M$8/$M$7*$E$17/$E$4*$E$18) -> 0.1900875
G21: Cla_AH estimation | H21: symbol | I21: value | O21: 0.17 | P21: =(O20-$H$5+0.05)/($I$13/$I$22*(1-$H$33)*$E$17/$E$4*$E$18) -> 0.0675845 | Q21: =(O20 + $M$6/$M$7 - $M$10)/($M$8/$M$7*$E$17/$E$4*$E$18) -> 0.182895
G22: Change of Cl with alpha for the wing w.r.t tail | H22: Cla_AH | I22: =I23*(1+2.15*E6/E5)*I28/E9*PI()/2*E6^2/E9 -> 0.3933752 | O22: 0.18 | P22: =(O21-$H$5+0.05)/($I$13/$I$22*(1-$H$33)*$E$17/$E$4*$E$18) -> 0.069386972 | Q22: =(O21 + $M$6/$M$7 - $M$10)/($M$8/$M$7*$E$17/$E$4*$E$18) -> 0.1757025
G23: CLaw (the change of CL with alpha for the wing) | H23: Cla_w | I23: =2*PI()*E20/(2 + SQRT(4 + (E20*I25/I26)^2*(1+TAN(I27)^2/I25^2))) -> 2.7482978 | O23: 0.19 | P23: =(O22-$H$5+0.05)/($I$13/$I$22*(1-$H$33)*$E$17/$E$4*$E$18) -> 0.071189444 | Q23: =(O22 + $M$6/$M$7 - $M$10)/($M$8/$M$7*$E$17/$E$4*$E$18) -> 0.16851
G24: Mach num for wing | H24: M_w | I24: 0.5 | O24: 0.2 | P24: =(O23-$H$5+0.05)/($I$13/$I$22*(1-$H$33)*$E$17/$E$4*$E$18) -> 0.072991916 | Q24: =(O23 + $M$6/$M$7 - $M$10)/($M$8/$M$7*$E$17/$E$4*$E$18) -> 0.1613175
G25: Beta for wing | H25: Beta_w | I25: =SQRT(1-I24^2) -> 0.8660254 | O25: 0.21 | P25: =(O24-$H$5+0.05)/($I$13/$I$22*(1-$H$33)*$E$17/$E$4*$E$18) -> 0.074794388 | Q25: =(O24 + $M$6/$M$7 - $M$10)/($M$8/$M$7*$E$17/$E$4*$E$18) -> 0.154125
G26: still no idea | H26: Eta_w | I26: 0.5 | O26: 0.22 | P26: =(O25-$H$5+0.05)/($I$13/$I$22*(1-$H$33)*$E$17/$E$4*$E$18) -> 0.07659686 | Q26: =(O25 + $M$6/$M$7 - $M$10)/($M$8/$M$7*$E$17/$E$4*$E$18) -> 0.1469325
G27: Taper ratio 0.5??? idk | H27: Lambda_0.5_h | I27: 0.5 | O27: 0.23 | P27: =(O26-$H$5+0.05)/($I$13/$I$22*(1-$H$33)*$E$17/$E$4*$E$18) -> 0.078399332 | Q27: =(O26 + $M$6/$M$7 - $M$10)/($M$8/$M$7*$E$17/$E$4*$E$18) -> 0.13974
G28: S less the projection of the central wing inside the fuselage | H28: S_net | I28: =E9 - '1.c)'!C33*E6 -> 61.521895 | O28: 0.24 | P28: =(O27-$H$5+0.05)/($I$13/$I$22*(1-$H$33)*$E$17/$E$4*$E$18) -> 0.080201804 | Q28: =(O27 + $M$6/$M$7 - $M$10)/($M$8/$M$7*$E$17/$E$4*$E$18) -> 0.1325475
O29: 0.25 | P29: =(O28-$H$5+0.05)/($I$13/$I$22*(1-$H$33)*$E$17/$E$4*$E$18) -> 0.082004276 | Q29: =(O28 + $M$6/$M$7 - $M$10)/($M$8/$M$7*$E$17/$E$4*$E$18) -> 0.125355
O30: 0.26 | P30: =(O29-$H$5+0.05)/($I$13/$I$22*(1-$H$33)*$E$17/$E$4*$E$18) -> 0.083806748 | Q30: =(O29 + $M$6/$M$7 - $M$10)/($M$8/$M$7*$E$17/$E$4*$E$18) -> 0.1181625
O31: 0.27 | P31: =(O30-$H$5+0.05)/($I$13/$I$22*(1-$H$33)*$E$17/$E$4*$E$18) -> 0.08560922 | Q31: =(O30 + $M$6/$M$7 - $M$10)/($M$8/$M$7*$E$17/$E$4*$E$18) -> 0.11097
G32: downwash approximation | O32: 0.28 | P32: =(O31-$H$5+0.05)/($I$13/$I$22*(1-$H$33)*$E$17/$E$4*$E$18) -> 0.087411692 | Q32: =(O31 + $M$6/$M$7 - $M$10)/($M$8/$M$7*$E$17/$E$4*$E$18) -> 0.1037775
G33: de/da | H33: 0.35 | O33: 0.29 | P33: =(O32-$H$5+0.05)/($I$13/$I$22*(1-$H$33)*$E$17/$E$4*$E$18) -> 0.089214164 | Q33: =(O32 + $M$6/$M$7 - $M$10)/($M$8/$M$7*$E$17/$E$4*$E$18) -> 0.096585
O34: 0.3 | P34: =(O33-$H$5+0.05)/($I$13/$I$22*(1-$H$33)*$E$17/$E$4*$E$18) -> 0.091016636 | Q34: =(O33 + $M$6/$M$7 - $M$10)/($M$8/$M$7*$E$17/$E$4*$E$18) -> 0.0893925
O35: 0.31 | P35: =(O34-$H$5+0.05)/($I$13/$I$22*(1-$H$33)*$E$17/$E$4*$E$18) -> 0.092819108 | Q35: =(O34 + $M$6/$M$7 - $M$10)/($M$8/$M$7*$E$17/$E$4*$E$18) -> 0.0822
O36: 0.32 | P36: =(O35-$H$5+0.05)/($I$13/$I$22*(1-$H$33)*$E$17/$E$4*$E$18) -> 0.09462158 | Q36: =(O35 + $M$6/$M$7 - $M$10)/($M$8/$M$7*$E$17/$E$4*$E$18) -> 0.0750075
O37: 0.33 | P37: =(O36-$H$5+0.05)/($I$13/$I$22*(1-$H$33)*$E$17/$E$4*$E$18) -> 0.096424052 | Q37: =(O36 + $M$6/$M$7 - $M$10)/($M$8/$M$7*$E$17/$E$4*$E$18) -> 0.067815
O38: 0.34 | P38: =(O37-$H$5+0.05)/($I$13/$I$22*(1-$H$33)*$E$17/$E$4*$E$18) -> 0.098226524 | Q38: =(O37 + $M$6/$M$7 - $M$10)/($M$8/$M$7*$E$17/$E$4*$E$18) -> 0.0606225
O39: 0.35 | P39: =(O38-$H$5+0.05)/($I$13/$I$22*(1-$H$33)*$E$17/$E$4*$E$18) -> 0.100029 | Q39: =(O38 + $M$6/$M$7 - $M$10)/($M$8/$M$7*$E$17/$E$4*$E$18) -> 0.05343
O40: 0.36 | P40: =(O39-$H$5+0.05)/($I$13/$I$22*(1-$H$33)*$E$17/$E$4*$E$18) -> 0.10183147 | Q40: =(O39 + $M$6/$M$7 - $M$10)/($M$8/$M$7*$E$17/$E$4*$E$18) -> 0.0462375
O41: 0.37 | P41: =(O40-$H$5+0.05)/($I$13/$I$22*(1-$H$33)*$E$17/$E$4*$E$18) -> 0.10363394 | Q41: =(O40 + $M$6/$M$7 - $M$10)/($M$8/$M$7*$E$17/$E$4*$E$18) -> 0.039045
...

Sheet 1.f)
C3: Cruise speed | L3: 230.555 | M3: m/s | N3: https://www.flyradius.com/bombardier-crj1000/specifications
C4: Approach speed | L4: 72.0222 | M4: m/s | N4: https://www.youtube.com/watch?v=nzRFznnfm7o&t=100s
C5: Tail-wing speed ratio (Vh/V) | L5: 1 | M5: - | N5: sead slides
C6: Lift rate coefficient of the tail at cruise speed
C7: Lift rate coefficient of the aircraft-less-tail at cruise speed, including the separate contributions of:
D8: Wing
D9: Fuselage
C10: Wing downwash gradient
C11: Position of the aerodynamic center of the aircraft-less-tail, evaluated both at cruise and approach speed, and including the following separate contributions:
D12: Wing
D13: Fuselage
D14: Nacelles
C15: Maximum horizontal tail lift coefficient (indicate also the type of tail, e.g. full moving, fixed, etc)
C16: Zero Lift pitching moment coefficient of the aircraft-less-tail, including the separate contributions of all the aircraft parts.

Sheet 2.a)
B3: EOW
B4: 23188 | C4: kg
B5: Table provided, expressed in percentage of the EOW | I5: Wing group | J5: mass (kg) | K5: XCG nose | L5: Xcg lemac | O5: Fuselage group | P5: mass (kg) | Q5: XCG nose | R5: Xcg lemac
B6: Component | C6: Weight (% EOW) | D6: mass (kg) | E6: updated mass | F6: OEW CG | I6: Wing | J6: =D7 -> 4568.036 | K6: =($J$6*C19+$J$7*C23)/$J$8 -> 19.994013 | L6: =($J$6*D19+$J$7*D23)/$J$8 -> 0.24401307 | O6: propulsion | P6: =D13 -> 3084.004 | Q6: =($P$6*C25+$P$7*C22+$P$8*C21+$P$9*C20+$P$10*C26+$P$11*C24)/SUM($P$6:$P$11) -> 20.404461 | R6: =($P$6*D25+$P$7*D22+$P$8*D21+$P$9*D20+$P$10*D26+$P$11*D24)/SUM($P$6:$P$11) -> 0.6544614
B7: Wing | C7: 19.7 | D7: =C7/100 *$B$4 -> 4568.036 | E7: =D7*0.91 -> 4156.9128 | F7: =SUMPRODUCT(D7:D14,C19:C26)/D15 -> 20.275564 | G7: from nose | I7: main landing gear | J7: =D11 -> 1344.904 | O7: fuselage | P7: =D10 -> 8115.8
B8: Horizontal Tail | C8: 2.5 | D8: =C8/100 *$B$4 -> 579.7 | F8: =SUMPRODUCT(D7:D14,D19:D26)/D15 -> 0.52556445 | G8: from LEMAC | J8: =SUM(J6:J7) -> 5912.94 | O8: vertical tail | P8: =D9 -> 417.384 | V8: Volume | Z8: new | AA8: new precent | AB8: change
B9: Vertical Tail | C9: 1.8 | D9: =C9/100 *$B$4 -> 417.384 | G9: lemac | O9: horizontal tail | P9: =D8 -> 579.7 | V9: Battery forward | X9: =1300/1000 -> 1.3 | Y9: m3
B10: Fuselage | C10: 35 | D10: =C10/100 *$B$4 -> 8115.8 | E10: =D10*0.93 -> 7547.694 | O10: cockpit | P10: =D14 -> 533.324 | V10: Gargo forward | X10: 5.26 | Y10: m3 | Z10: =X10-X9 -> 3.96 | AA10: =Z10/X10 * 100 -> 75.285171 | AB10: =100-AA10 -> 24.714829
B11: Main Landing gear | C11: 5.8 | D11: =C11/100 *$B$4 -> 1344.904 | O11: nose landing gear | P11: =D12 -> 185.504 | V11: Battery backward | X11: 1.6 | Y11: m3
B12: Nose Landing gear | C12: 0.8 | D12: =C12/100 *$B$4 -> 185.504 | P12: =SUM(P6:P11) -> 12915.716 | V12: Gargo backward | X12: 14.41 | Y12: m3 | Z12: =X12-X11 -> 12.81 | AA12: =Z12/X12 * 100 -> 88.8966 | AB12: =100-AA12 -> 11.1034
B13: Propulsion System | C13: 13.3 | D13: =C13/100 *$B$4 -> 3084.004
B14: Cockpit Systems | C14: 2.3 | D14: =C14/100 *$B$4 -> 533.324
B15: Total | C15: =SUM(C7:C14) -> 81.2 | D15: =C15/100 *$B$4 -> 18828.656 | K15: 2.b | V15: start | W15: =X12/4.17 -> 3.4556355
C16: 100 | D16: =C16/100 *$B$4 -> 23188 | V16: backward
K17: Number | L17: inpact | M17: what modification | X17: AREA | Y17: BATT length
B18: CG | C18: cg position from front | D18: position from LEMAC | K18: 1 | L18: engines | M18: engines 20 procent increase length and diameter | X18: =X12/4.17 -> 3.4556355 | Y18: =X11/X18 -> 0.4630118
B19: Wing | C19: =16.3+(2/3)*5.11 -> 19.706667 | D19: =C19-$C$27 -> -0.043333333 | F19: [m] | K19: 2 | L19: engines | M19: no weight or cg change
B20: Horizontal Tail | C20: 36.5 | D20: =C20-$C$27 -> 16.75 | F20: [m] | K20: 3 | L20: wing & fuselage | M20: -9 procent weight and -7 for weight fuselage
B21: Vertical Tail | C21: 36 | D21: =C21-$C$27 -> 16.25 | F21: [m] | K21: 4 | L21: forward cargo hold & back gargo hold | M21: 2025 kg in forward hold, 2475 kg in backward hold
B22: Fuselage | C22: =((28.6-C26*2)/2)+(C26*2) -> 16.535 | D22: =C22-$C$27 -> -3.215 | F22: [m] | K22: 5 | L22: new EOW with battery
B23: Main Landing gear | C23: 20.97 | D23: =C23-$C$27 -> 1.22 | F23: [m] | K23: 6 | L23: pax | M23: last 3 rows (12 seats are removed)
B24: Nose Landing gear | C24: 2.17 | D24: =C24-$C$27 -> -17.58 | F24: [m] | K24: 7 | L24: cargo | M24: cargo weight steads the same, but different distrubtion (less volume)
B25: Propulsion System | C25: =28.6+1.09 -> 29.69 | D25: =C25-$C$27 -> 9.94 | F25: [m] | K25: 8 | L25: MTOW | M25: MTOW says the same -> less fuel bc of batteries
B26: Cockpit Systems | C26: =4.47/2 -> 2.235 | D26: =C26-$C$27 -> -17.515 | F26: [m] | K26: 9 | L26: Wing AR | M26: 25 procent bigger
B27: nose to lemac | C27: =16.3+3.45 -> 19.75 | K27: 10 | L27: Maximum CL | M27: 20 procent bigger
K28: 11 | L28: landing gear | M28: 30 cm higher
B29: LEMAC Calculation prerequisites | E29: source
B30: Wing surface | C30: 77.39 | D30: [m2] | E30: CPJ1000APMR8
B31: wing span | C31: 26.17 | D31: [m] | E31: CPJ1000APMR8
B32: taper | C32: 0.23812887 | D32: [-] | E32: CPJ1000APMR8
B33: root chord | C33: 5.8879795 | D33: [m] | E33: CRJ1000APMR8
B34: tip chord | C34: =C33*C32 -> 1.4020979 | D34: [m] | E34: CPJ1000APMR8 | K34: change 3
B35: sweep | C35: 30 | D35: degrees | E35: CPJ1000APMR8
B36: aspect ratio | C36: =C31*C31/C30 -> 8.8495788 | D36: [-] | E36: CPJ1000APMR8
B41: number passangers | C41: 88
B42: n rows | C42: =C41/C43 -> 22
B43: seat per row | C43: 4
B44: seat pitch | C44: =31*0.0254 -> 0.7874 | D44: [m]
B45: first row longitudinal position | C45: 6.75 | D45: [m]
B46: passenger mass per | C46: 90 | D46: [kg]
...

Sheet 2.a_2)_RIK
A1: ='1.c)'!B3 -> EOW
A2: ='1.c)'!B4 -> 23188 | B2: ='1.c)'!C4 -> kg
A3: ='1.c)'!B5 -> Table provided, expressed in percentage of the EOW | G3: ='1.c)'!H5 -> Wing group | H3: ='1.c)'!I5 -> mass (kg) | I3: ='1.c)'!J5 -> XCG nose | J3: ='1.c)'!K5 -> Xcg lemac | M3: ='1.c)'!N5 -> Fuselage group | N3: ='1.c)'!O5 -> mass (kg) | O3: ='1.c)'!P5 -> XCG nose | P3: ='1.c)'!Q5 -> Xcg lemac | T3: NEW weights precentages
A4: ='1.c)'!B6 -> Component | B4: ='1.c)'!C6 -> Weight (% EOW) | C4: ='1.c)'!D6 -> mass (kg) | D4: ='1.c)'!E6 -> OEW CG | G4: ='1.c)'!H6 -> Wing | H4: ='1.c)'!I6 -> 4568.036 | I4: ='1.c)'!J6 -> 20.861433 | J4: ='1.c)'!K6 -> 1.1062987 | M4: ='1.c)'!N6 -> propulsion | N4: ='1.c)'!O6 -> 3084.004 | O4: ='1.c)'!P6 -> 20.815803 | P4: ='1.c)'!Q6 -> 1.0606688
A5: ='1.c)'!B7 -> Wing | B5: ='1.c)'!C7 -> 19.7 | C5: ='1.c)'!D7 -> 4568.036 | D5: ='1.c)'!E7 -> 20.830133 | E5: ='1.c)'!F7 -> from nose | G5: ='1.c)'!H7 -> main landing gear | H5: ='1.c)'!I7 -> 1344.904 | M5: ='1.c)'!N7 -> fuselage | N5: ='1.c)'!O7 -> 8115.8 | T5: =A4 -> Component | U5: =B4 -> Weight (% EOW) | V5: =C4 -> mass (kg) | AB5: abs [kg] | AC5: %MTOW
A6: ='1.c)'!B8 -> Horizontal Tail | B6: ='1.c)'!C8 -> 2.5 | C6: ='1.c)'!D8 -> 579.7 | D6: ='1.c)'!E8 -> 1.0749984 | E6: ='1.c)'!F8 -> from LEMAC | G6: ='1.c)'!H8 -> Total | H6: ='1.c)'!I8 -> 5912.94 | M6: ='1.c)'!N8 -> vertical tail | N6: ='1.c)'!O8 -> 417.384 | T6: Wing_new | U6: =V6/$U$21 * 100 -> 15.86077 | V6: =C5*0.91 -> 4156.9128 | Z6: MTOW | AB6: 38995 | AC6: 100
A7: ='1.c)'!B9 -> Vertical Tail | B7: ='1.c)'!C9 -> 1.8 | C7: ='1.c)'!D9 -> 417.384 | E7: ='1.c)'!F9 -> lemac | M7: ='1.c)'!N9 -> horizontal tail | N7: ='1.c)'!O9 -> 579.7 | T7: =A6 -> Horizontal Tail | U7: =V7/$U$21 * 100 -> 2.211855 | V7: =C6 -> 579.7 | Z7: OEW_NEW | AB7: 26209 | AC7: =AB7/$AB$6 * 100 -> 67.211181
A8: ='1.c)'!B10 -> Fuselage | B8: ='1.c)'!C10 -> 35 | C8: ='1.c)'!D10 -> 8115.8 | M8: ='1.c)'!N10 -> cockpit | N8: ='1.c)'!O10 -> 533.324 | T8: =A7 -> Vertical Tail | U8: =V8/$U$21 * 100 -> 1.5925356 | V8: =C7 -> 417.384 | Z8: Fuel weight @ max payload | AB8: =AB6-AB7-AB9 -> 1923.64 | AC8: =AB8/$AB$6 * 100 -> 4.9330427
A9: ='1.c)'!B11 -> Main Landing gear | B9: ='1.c)'!C11 -> 5.8 | C9: ='1.c)'!D11 -> 1344.904 | M9: ='1.c)'!N11 -> nose landing gear | N9: ='1.c)'!O11 -> 185.504 | T9: Fuselage_new | U9: =V9/$U$21 * 100 -> 28.798352 | V9: =C8*0.93 -> 7547.694 | Z9: Max payload | AA9: Max payload | AB9: =SUM(AB10:AB12) -> 10862.36 | AC9: =AB9/$AB$6 * 100 -> 27.855776
A10: ='1.c)'!B12 -> Nose Landing gear | B10: ='1.c)'!C12 -> 0.8 | C10: ='1.c)'!D12 -> 185.504 | M10: ='1.c)'!N12 -> Total | N10: ='1.c)'!O12 -> 12915.716 | T10: =A9 -> Main Landing gear | U10: =V10/$U$21 * 100 -> 5.1315035 | V10: =C9 -> 1344.904 | AA10: Pax&cabin luggage | AB10: 8093.36 | AC10: =AB10/$AB$6 * 100 -> 20.754866
A11: ='1.c)'!B13 -> Propulsion System | B11: ='1.c)'!C13 -> 13.3 | C11: ='1.c)'!D13 -> 3084.004 | T11: =A10 -> Nose Landing gear | U11: =V11/$U$21 * 100 -> 0.70779359 | V11: =C10 -> 185.504 | AA11: Front cargo hold | AB11: 962 | AC11: =AB11/$AB$6 * 100 -> 2.4669829
A12: ='1.c)'!B14 -> Cockpit Systems | B12: ='1.c)'!C14 -> 2.3 | C12: ='1.c)'!D14 -> 533.324 | T12: =A11 -> Propulsion System | U12: =V12/$U$21 * 100 -> 11.767068 | V12: =C11 -> 3084.004 | AA12: Aft cargo hold | AB12: 1807 | AC12: =AB12/$AB$6 * 100 -> 4.6339274
A13: ='1.c)'!B15 -> Total | B13: ='1.c)'!C15 -> 81.2 | C13: ='1.c)'!D15 -> 18828.656 | O13: Extra orginal OEW (Not contibuting to CG) | T13: =A12 -> Cockpit Systems | U13: =V13/$U$21 * 100 -> 2.0349066 | V13: =C12 -> 533.324
O14: =(100-B13)/100 *A2 -> 4359.344 | P14: [kg] | T14: Batteries | U14: =V14/$U$21 * 100 -> 15.262066 | V14: 4000
T15: =A14 -> 0 | U15: =SUM(U6:U14) -> 83.366851 | V15: =SUM(V6:V14) -> 21849.427 | Z15: Slice labels
A16: ='1.c)'!B18 -> CG | B16: ='1.c)'!C18 -> cg position from front | C16: ='1.c)'!D18 -> position from LEMAC | G16: ='1.c)'!H18 -> CRJ1000 geometry | Z16: OEW
A17: ='1.c)'!B19 -> Wing | B17: ='1.c)'!C19 -> 20.829469 | C17: ='1.c)'!D19 -> 1.0743348 | D17: ='1.c)'!E19 -> [m] | G17: ='1.c)'!H19 -> Fuselage length | H17: ='1.c)'!I19 -> 36.466 | I17: m | T17: new operating empty weight | Z17: Fuel weight @ max payload
A18: ='1.c)'!B20 -> Horizontal Tail | B18: ='1.c)'!C20 -> 36.951365 | C18: ='1.c)'!D20 -> 17.19623 | D18: ='1.c)'!E20 -> [m] | T18: Components | U18: =V15 -> 21849.427 | V18: [kg] | Z18: Max payload
A19: ='1.c)'!B21 -> Vertical Tail | B19: ='1.c)'!C21 -> 35.166369 | C19: ='1.c)'!D21 -> 15.411234 | D19: ='1.c)'!E21 -> [m] | T19: Extra weights | U19: =O14 -> 4359.344 | V19: [kg] | Z19: Pax&cabin luggage
A20: ='1.c)'!B22 -> Fuselage | B20: ='1.c)'!C22 -> 17.13902 | C20: ='1.c)'!D22 -> -2.6161144 | D20: ='1.c)'!E22 -> [m] | Z20: Front cargo hold
A21: ='1.c)'!B23 -> Main Landing gear | B21: ='1.c)'!C23 -> 20.97 | C21: ='1.c)'!D23 -> 1.2148656 | D21: ='1.c)'!E23 -> [m] | T21: Total | U21: =SUM(U18:U20) -> 26208.771 | Z21: Aft cargo hold
A22: ='1.c)'!B24 -> Nose Landing gear | B22: ='1.c)'!C24 -> 2.17 | C22: ='1.c)'!D24 -> -17.585134 | D22: ='1.c)'!E24 -> [m]
A23: ='1.c)'!B25 -> Propulsion System | B23: ='1.c)'!C25 -> 29.85114 | C23: ='1.c)'!D25 -> 10.096006 | D23: ='1.c)'!E25 -> [m] | T23: New passenger weight
A24: ='1.c)'!B26 -> Cockpit Systems | B24: ='1.c)'!C26 -> 2.235 | C24: ='1.c)'!D26 -> -17.520134 | D24: ='1.c)'!E26 -> [m] | U24: kg | V24: n people
A25: ='1.c)'!B27 -> nose to lemac | B25: ='1.c)'!C27 -> 19.755134 | T25: old PAX | U25: 9197 | V25: 100
I26: Number | J26: inpact | K26: what modification | U26: =U25/V25 -> 91.97 | V26: 1
A27: ='1.c)'!B29 -> LEMAC Calculation prerequisites | D27: ='1.c)'!E29 -> source | I27: 1 | J27: engines | K27: engines 20 procent increase length and diameter | U27: =U26*V27 -> 8093.36 | V27: 88
A28: ='1.c)'!B30 -> Wing surface | B28: ='1.c)'!C30 -> 77.39 | C28: ='1.c)'!D30 -> [m2] | D28: ='1.c)'!E30 -> CPJ1000APMR8 | I28: 2 | J28: engines | K28: no weight or cg change
A29: ='1.c)'!B31 -> wing span | B29: ='1.c)'!C31 -> 26.175 | C29: ='1.c)'!D31 -> [m] | D29: ='1.c)'!E31 -> CPJ1000APMR8 | I29: 3 | J29: wing & fuselage | K29: -9 procent weight and -7 for weight fuselage | T29: precentage of extra weight (not contributing to cg)
A30: ='1.c)'!B32 -> taper | B30: ='1.c)'!C32 -> 0.23812887 | C30: ='1.c)'!D32 -> [-] | D30: ='1.c)'!E32 -> CPJ1000APMR8 | I30: 4 | J30: forward cargo hold & back gargo hold | K30: 2025 kg in forward hold, 2475 kg in backward hold | T30: =O14/U21*100 -> 16.633149 | U30: =100-T30 -> 83.366851
A31: ='1.c)'!B33 -> root chord | B31: ='1.c)'!C33 -> 5.8879795 | C31: ='1.c)'!D33 -> [m] | D31: ='1.c)'!E33 -> CRJ1000APMR8 | I31: 5 | J31: new EOW with battery
A32: ='1.c)'!B34 -> tip chord | B32: ='1.c)'!C34 -> 1.4020979 | C32: ='1.c)'!D34 -> [m] | D32: ='1.c)'!E34 -> CPJ1000APMR8 | I32: 6 | J32: pax | K32: last 3 rows (12 seats are removed)
A33: ='1.c)'!B35 -> sweep | B33: ='1.c)'!C35 -> 30 | C33: ='1.c)'!D35 -> degrees | D33: ='1.c)'!E35 -> CPJ1000APMR8 | I33: 7 | J33: cargo | K33: cargo weight steads the same, but different distrubtion (less volume)
A34: ='1.c)'!B36 -> aspect ratio | B34: ='1.c)'!C36 -> 8.8529607 | C34: ='1.c)'!D36 -> [-] | D34: ='1.c)'!E36 -> CPJ1000APMR8 | I34: 8 | J34: MTOW | K34: MTOW says the same -> less fuel bc of batteries
I35: 9 | J35: Wing AR | K35: 25 procent bigger
I36: 10 | J36: Maximum CL | K36: 20 procent bigger
I37: 11 | J37: landing gear | K37: 30 cm higher
A39: Number of passengers | B39: 100 | C39: [-] | K39: %
A40: ='1.c)'!B42 -> n rows | B40: ='1.c)'!C42 -> 20 | C40: [-] | I40: Engines | J40: Length and diameter | K40: 20
A41: ='1.c)'!B43 -> seat per row | B41: ='1.c)'!C43 -> 5 | C41: [-] | J41: Weight or CG shift | K41: -
...

Sheet 2.b)
